INFO root Starting application...
ERROR root Traceback (most recent call last):
  File "lab_five.py", line 71, in main
    analyze_population_data(population_data_frame)
  File "lab_five.py", line 144, in analyze_population_data
    print(input_confirmation)
UnboundLocalError: local variable 'input_confirmation' referenced before assignment

ERROR root Traceback (most recent call last):
  File "lab_five.py", line 81, in main
    housing_file = open(housing_f_name, 'r')
FileNotFoundError: [Errno 2] No such file or directory: 'Housing.csv'

ERROR root Traceback (most recent call last):
  File "lab_five.py", line 83, in main
    analyze_housing_data(housing_data_frame)
  File "lab_five.py", line 192, in analyze_housing_data
    print(housing_df.column[col].describe())
  File "/home/lindell/.local/lib/python3.6/site-packages/pandas/core/generic.py", line 5141, in __getattr__
    return object.__getattribute__(self, name)
AttributeError: 'DataFrame' object has no attribute 'column'

ERROR root Traceback (most recent call last):
  File "/home/lindell/.local/lib/python3.6/site-packages/pandas/core/indexes/base.py", line 2898, in get_loc
    return self._engine.get_loc(casted_key)
  File "pandas/_libs/index.pyx", line 70, in pandas._libs.index.IndexEngine.get_loc
  File "pandas/_libs/index.pyx", line 101, in pandas._libs.index.IndexEngine.get_loc
  File "pandas/_libs/hashtable_class_helper.pxi", line 1675, in pandas._libs.hashtable.PyObjectHashTable.get_item
  File "pandas/_libs/hashtable_class_helper.pxi", line 1683, in pandas._libs.hashtable.PyObjectHashTable.get_item
KeyError: 0

The above exception was the direct cause of the following exception:

Traceback (most recent call last):
  File "lab_five.py", line 83, in main
    analyze_housing_data(housing_data_frame)
  File "lab_five.py", line 192, in analyze_housing_data
    print(housing_df[col].describe())
  File "/home/lindell/.local/lib/python3.6/site-packages/pandas/core/frame.py", line 2906, in __getitem__
    indexer = self.columns.get_loc(key)
  File "/home/lindell/.local/lib/python3.6/site-packages/pandas/core/indexes/base.py", line 2900, in get_loc
    raise KeyError(key) from err
KeyError: 0

ERROR root Traceback (most recent call last):
  File "/home/lindell/.local/lib/python3.6/site-packages/pandas/core/indexes/base.py", line 2898, in get_loc
    return self._engine.get_loc(casted_key)
  File "pandas/_libs/index.pyx", line 70, in pandas._libs.index.IndexEngine.get_loc
  File "pandas/_libs/index.pyx", line 101, in pandas._libs.index.IndexEngine.get_loc
  File "pandas/_libs/hashtable_class_helper.pxi", line 1675, in pandas._libs.hashtable.PyObjectHashTable.get_item
  File "pandas/_libs/hashtable_class_helper.pxi", line 1683, in pandas._libs.hashtable.PyObjectHashTable.get_item
KeyError: 0

The above exception was the direct cause of the following exception:

Traceback (most recent call last):
  File "lab_five.py", line 83, in main
    analyze_housing_data(housing_data_frame)
  File "lab_five.py", line 192, in analyze_housing_data
    print(housing_df[col].describe())
  File "/home/lindell/.local/lib/python3.6/site-packages/pandas/core/frame.py", line 2906, in __getitem__
    indexer = self.columns.get_loc(key)
  File "/home/lindell/.local/lib/python3.6/site-packages/pandas/core/indexes/base.py", line 2900, in get_loc
    raise KeyError(key) from err
KeyError: 0

ERROR root Traceback (most recent call last):
  File "lab_five.py", line 83, in main
    analyze_housing_data(housing_data_frame)
  File "lab_five.py", line 192, in analyze_housing_data
    print(housing_df.columns[col].describe())
AttributeError: 'str' object has no attribute 'describe'

ERROR root Traceback (most recent call last):
  File "lab_five.py", line 83, in main
    analyze_housing_data(housing_data_frame)
  File "lab_five.py", line 192, in analyze_housing_data
    print(housing_df.col.describe())
  File "/home/lindell/.local/lib/python3.6/site-packages/pandas/core/generic.py", line 5141, in __getattr__
    return object.__getattribute__(self, name)
AttributeError: 'DataFrame' object has no attribute 'col'

ERROR root Traceback (most recent call last):
  File "lab_five.py", line 83, in main
    analyze_housing_data(housing_data_frame)
  File "lab_five.py", line 192, in analyze_housing_data
    print(housing_df.housing_df[col].describe())
  File "/home/lindell/.local/lib/python3.6/site-packages/pandas/core/generic.py", line 5141, in __getattr__
    return object.__getattribute__(self, name)
AttributeError: 'DataFrame' object has no attribute 'housing_df'

ERROR root Traceback (most recent call last):
  File "/home/lindell/.local/lib/python3.6/site-packages/pandas/core/indexes/base.py", line 2898, in get_loc
    return self._engine.get_loc(casted_key)
  File "pandas/_libs/index.pyx", line 70, in pandas._libs.index.IndexEngine.get_loc
  File "pandas/_libs/index.pyx", line 101, in pandas._libs.index.IndexEngine.get_loc
  File "pandas/_libs/hashtable_class_helper.pxi", line 1675, in pandas._libs.hashtable.PyObjectHashTable.get_item
  File "pandas/_libs/hashtable_class_helper.pxi", line 1683, in pandas._libs.hashtable.PyObjectHashTable.get_item
KeyError: 0

The above exception was the direct cause of the following exception:

Traceback (most recent call last):
  File "lab_five.py", line 83, in main
    analyze_housing_data(housing_data_frame)
  File "lab_five.py", line 192, in analyze_housing_data
    print(housing_df.describe()[col])
  File "/home/lindell/.local/lib/python3.6/site-packages/pandas/core/frame.py", line 2906, in __getitem__
    indexer = self.columns.get_loc(key)
  File "/home/lindell/.local/lib/python3.6/site-packages/pandas/core/indexes/base.py", line 2900, in get_loc
    raise KeyError(key) from err
KeyError: 0

ERROR root Traceback (most recent call last):
  File "/home/lindell/.local/lib/python3.6/site-packages/pandas/core/indexes/base.py", line 2898, in get_loc
    return self._engine.get_loc(casted_key)
  File "pandas/_libs/index.pyx", line 70, in pandas._libs.index.IndexEngine.get_loc
  File "pandas/_libs/index.pyx", line 101, in pandas._libs.index.IndexEngine.get_loc
  File "pandas/_libs/hashtable_class_helper.pxi", line 1675, in pandas._libs.hashtable.PyObjectHashTable.get_item
  File "pandas/_libs/hashtable_class_helper.pxi", line 1683, in pandas._libs.hashtable.PyObjectHashTable.get_item
KeyError: 4

The above exception was the direct cause of the following exception:

Traceback (most recent call last):
  File "lab_five.py", line 71, in main
    analyze_population_data(population_data_frame)
  File "lab_five.py", line 138, in analyze_population_data
    print(pop_df.describe()[col])
  File "/home/lindell/.local/lib/python3.6/site-packages/pandas/core/frame.py", line 2906, in __getitem__
    indexer = self.columns.get_loc(key)
  File "/home/lindell/.local/lib/python3.6/site-packages/pandas/core/indexes/base.py", line 2900, in get_loc
    raise KeyError(key) from err
KeyError: 4

ERROR root Traceback (most recent call last):
  File "/home/lindell/.local/lib/python3.6/site-packages/pandas/core/indexes/base.py", line 2898, in get_loc
    return self._engine.get_loc(casted_key)
  File "pandas/_libs/index.pyx", line 70, in pandas._libs.index.IndexEngine.get_loc
  File "pandas/_libs/index.pyx", line 101, in pandas._libs.index.IndexEngine.get_loc
  File "pandas/_libs/hashtable_class_helper.pxi", line 1675, in pandas._libs.hashtable.PyObjectHashTable.get_item
  File "pandas/_libs/hashtable_class_helper.pxi", line 1683, in pandas._libs.hashtable.PyObjectHashTable.get_item
KeyError: 6

The above exception was the direct cause of the following exception:

Traceback (most recent call last):
  File "lab_five.py", line 71, in main
    analyze_population_data(population_data_frame)
  File "lab_five.py", line 138, in analyze_population_data
    print(pop_df.describe()[pop_df[col]])
  File "/home/lindell/.local/lib/python3.6/site-packages/pandas/core/frame.py", line 2906, in __getitem__
    indexer = self.columns.get_loc(key)
  File "/home/lindell/.local/lib/python3.6/site-packages/pandas/core/indexes/base.py", line 2900, in get_loc
    raise KeyError(key) from err
KeyError: 6

ERROR root Traceback (most recent call last):
  File "/home/lindell/.local/lib/python3.6/site-packages/pandas/core/indexes/base.py", line 2898, in get_loc
    return self._engine.get_loc(casted_key)
  File "pandas/_libs/index.pyx", line 70, in pandas._libs.index.IndexEngine.get_loc
  File "pandas/_libs/index.pyx", line 101, in pandas._libs.index.IndexEngine.get_loc
  File "pandas/_libs/hashtable_class_helper.pxi", line 1675, in pandas._libs.hashtable.PyObjectHashTable.get_item
  File "pandas/_libs/hashtable_class_helper.pxi", line 1683, in pandas._libs.hashtable.PyObjectHashTable.get_item
KeyError: 6

The above exception was the direct cause of the following exception:

Traceback (most recent call last):
  File "lab_five.py", line 71, in main
    analyze_population_data(population_data_frame)
  File "lab_five.py", line 140, in analyze_population_data
    print(pop_df.describe()[pop_df[col]])
  File "/home/lindell/.local/lib/python3.6/site-packages/pandas/core/frame.py", line 2906, in __getitem__
    indexer = self.columns.get_loc(key)
  File "/home/lindell/.local/lib/python3.6/site-packages/pandas/core/indexes/base.py", line 2900, in get_loc
    raise KeyError(key) from err
KeyError: 6

